<?xml version="1.0"?>

<robot name="maieutic">
    <!-- Linkages -->
    <link name="lk0">
        <visual>
	    <origin xyz="0.0 0.0 0.0" rpy="0.0 0.0 0.0"/>
	    <geometry>
	        <mesh filename="../meshes/visual/lk0.dae" scale="1.0 1.0 1.0"/>
	    </geometry>
	    <material name="dark_grey">
    	    	<color rgba="0.4 0.4 0.4 1.0"/>
    	    </material>
	</visual>
	<collision>
	    <origin xyz="0.0 0.0 0.0" rpy="0.0 0.0 0.0"/>
	    <geometry>
	        <mesh filename="../meshes/collision/lk0.stl" scale="0.001 0.001 0.001"/>
	    </geometry>
	</collision>
	<inertial>
	    <origin xyz="0.0 0.0 0.0" rpy="0.0 0.0 0.0"/>
	    <mass value="1.0"/>
	    <inertia ixx="1" ixy="0" ixz="0" iyy="1" iyz="0" izz="1"/>
	</inertial>
    </link>

    <link name="lk1">
        <visual>
	    <origin xyz="0.0 0.0 0.0" rpy="0.0 0.0 0.0"/>
	    <geometry>
		<mesh filename="../meshes/visual/lk1.dae" scale="1.0 1.0 1.0"/>
	    </geometry>
	    <material name="white">
                <color rgba="1.0 1.0 1.0 1.0"/>
            </material>
	</visual>
	<collision>
            <origin xyz="0.0 0.0 0.0" rpy="0.0 0.0 0.0"/>
            <geometry>                                   
                <mesh filename="../meshes/collision/lk1.stl" scale="0.001 0.001 0.001"/>
            </geometry>
        </collision>
	<inertial>
	    <origin xyz="0.0 0.0 0.0" rpy="0.0 0.0 0.0"/>
	    <mass value="1.0"/>
	    <inertia ixx="1" ixy="0" ixz="0" iyy="1" iyz="0" izz="1"/>
	</inertial>
    </link>

    <link name="lk2">
        <visual>
	    <origin xyz="0.0 0.0 0.0" rpy="0.0 0.0 0.0"/>
	    <geometry>
              <mesh filename="../meshes/visual/lk2.dae" scale="1.0 1.0 1.0"/>
	    </geometry>
            <material name="white">
    	    	<color rgba="1.0 1.0 1.0 1.0"/>
    	    </material>
	</visual>
	<collision>           
            <origin xyz="0.0 0.0 0.0" rpy="0.0 0.0 0.0"/>
            <geometry>                                   
                <mesh filename="../meshes/collision/lk2.stl" scale="0.001 0.001 0.001"/>
            </geometry>
        </collision>
	<inertial>
	    <origin xyz="0.0 0.0 0.0" rpy="0.0 0.0 0.0"/>
	    <mass value="1.0"/>
	    <inertia ixx="1" ixy="0" ixz="0" iyy="1" iyz="0" izz="1"/>
	</inertial>
    </link>

    <!-- Joints -->
    <joint name="q1" type="revolute">
	<parent link="lk0"/>
	<child link="lk1"/>
	<axis xyz="0.0 0.0 1.0"/>
	<limit lower="-3.1416" upper="3.1416" effort="1.0" velocity="1.0"/>
	<origin xyz="0.0 0.0 0.047" rpy="0.0 0.0 0.0"/>
    </joint>

    <joint name="q2" type="revolute">
	<parent link="lk1"/>
	<child link="lk2"/>
	<axis xyz="0.0 0.0 1.0"/>
	<limit lower="-3.1416" upper="3.1416" effort="1.0" velocity="1.0"/>
	<origin xyz="0.0 -0.035 0.0305" rpy="1.5707963 0.0 0.0"/>
    </joint>
</robot>
